Workbook

Sheet Dashboard
A1: STOCK ANALYSIS DASHBOARD
A2: Ticker Symbol: | C2: =Analysis!$B$2 -> WMT | D2: Current Price: | E2: =Valuation!F29 -> 123.63 | G2: Signal: | I2: =IFERROR(IF(H20>0.25,"STRONG BUY",IF(H20>0.1,"BUY",IF(H20>-0.1,"HOLD",IF(H20>-0.25,"SELL","STRONG SELL")))),"N/A") -> STRONG SELL | K2: DCF CASES
D3: Market Cap: | E3: =Calculations!C16 -> 991759860 | G3: Last Updated: | I3: ='Raw Data Pasting'!E4 -> 46105 | K3: Scenario | L3: Intrinsic Value | M3: vs. Current Price | N3: IRR (5-Year) | O3: 5-Yr Total Return
A4: Fundamentals | K4: Bear Case | L4: =Valuation!K48 -> 9.2519813 | M4: =Valuation!K49 -> -0.92516395 | N4: =Valuation!K50 -> -0.4045817 | O4: =Valuation!K51 -> -0.92516395
A5: P/E Ratio | B5: =Calculations!C50 -> 45.285714 | C5: =IFERROR("Rating: "&TEXT(Analysis!E38,"0.0")&" / 5.0","N/A") -> Rating: 1.0 / 5.0 | K5: Base Case | L5: =Valuation!J48 -> 85.308313 | M5: =Valuation!J49 -> -0.30997077 | N5: =Valuation!J50 -> -0.071517981 | O5: =Valuation!J51 -> -0.30997077
A6: Debt/Equity | B6: =Analysis!B21 -> 0.63189866 | C6: =IFERROR("Rating: "&TEXT(Analysis!F21,"0.0")&" / 5.0","N/A") -> Rating: 3.5 / 5.0 | K6: Bull Case | L6: =Valuation!I48 -> 265.43046 | M6: =Valuation!I49 -> 1.1469746 | N6: =Valuation!I50 -> 0.16510584 | O6: =Valuation!I51 -> 1.1469746
A7: EV/EBITDA | B7: ='Data Schema'!B49 -> 21.63 | C7: =IFERROR("Rating: "&TEXT(Analysis!E41,"0.0")&" / 5.0","N/A") -> Rating: 1.0 / 5.0 | K7: Monte Carlo Mean | L7: =Valuation!B159 -> 96.290976 | M7: =IFERROR((Valuation!B159-Valuation!F29)/Valuation!F29,0) -> -0.22113584 | N7: =IFERROR((Valuation!J145/Valuation!F29)^(1/5)-1,0) -> -1 | O7: =IFERROR(Valuation!J145/Valuation!F29-1,0) -> -1
A8: Current Ratio | B8: =Analysis!B15 -> 0.78975332 | C8: =IFERROR("Rating: "&TEXT(Analysis!F15,"0.0")&" / 5.0","N/A") -> Rating: 2.5 / 5.0
A9: ROE | B9: =Analysis!B9 -> 0.20618761 | C9: =IFERROR("Rating: "&TEXT(Analysis!F9,"0.0")&" / 5.0","N/A") -> Rating: 5.0 / 5.0
A10: Operating Margin | B10: =Analysis!B7 -> 0.045246318 | C10: =IFERROR("Rating: "&TEXT(Analysis!F7,"0.0")&" / 5.0","N/A") -> Rating: 3.5 / 5.0
A11: ROIC | B11: =Analysis!B11 -> 0.15001864 | C11: =IFERROR("Rating: "&TEXT(Analysis!F11,"0.0")&" / 5.0","N/A") -> Rating: 5.0 / 5.0
A12: Rev Growth (YoY) | B12: =Analysis!B32 -> 0.047252142 | C12: =IFERROR("Rating: "&TEXT(Analysis!F32,"0.0")&" / 5.0","N/A") -> Rating: 1.5 / 5.0
A13: FINANCIAL HEALTH SCORECARD
A14: Profitability | B14: =Analysis!F12 -> 4.1666667 | C14: =IFERROR(REPT("█",ROUND(B14,0))&REPT("░",5-ROUND(B14,0))&" "&TEXT(B14,"0.0")&" / 5.0","N/A") -> ████░ 4.2 / 5.0
A15: Liquidity | B15: =Analysis!F18 -> 2.1666667 | C15: =IFERROR(REPT("█",ROUND(B15,0))&REPT("░",5-ROUND(B15,0))&" "&TEXT(B15,"0.0")&" / 5.0","N/A") -> ██░░░ 2.2 / 5.0
A16: Leverage/Risk | B16: =Analysis!F24 -> 4 | C16: =IFERROR(REPT("█",ROUND(B16,0))&REPT("░",5-ROUND(B16,0))&" "&TEXT(B16,"0.0")&" / 5.0","N/A") -> ████░ 4.0 / 5.0 | K16: MONTE CARLO SIMULATION FOR DCF
A17: Efficiency | B17: =Analysis!F29 -> 3.25 | C17: =IFERROR(REPT("█",ROUND(B17,0))&REPT("░",5-ROUND(B17,0))&" "&TEXT(B17,"0.0")&" / 5.0","N/A") -> ███░░ 3.3 / 5.0 | G17: VALUATIONS | K17: =Valuation!A174 -> Based on 1000 simulations with constraints, 795 valid scenarios were analyzed. There is a 27.7% chance that the intrinsic value exceeds the current market price of $123.63. The 80% confidence interval is $36.89 to $167.96.
A18: Growth | B18: =Analysis!F35 -> 2.3333333 | C18: =IFERROR(REPT("█",ROUND(B18,0))&REPT("░",5-ROUND(B18,0))&" "&TEXT(B18,"0.0")&" / 5.0","N/A") -> ██░░░ 2.3 / 5.0 | G18: DCF | H18: =Valuation!F28 -> 85.308313 | I18: Peer Multiples | J18: =IF(Valuation!F100="On",Valuation!D106,"Off") -> 76.106156
A19: Valuation | B19: =Analysis!E43 -> 1 | C19: =IFERROR(REPT("█",ROUND(B19,0))&REPT("░",5-ROUND(B19,0))&" "&TEXT(B19,"0.0")&" / 5.0","N/A") -> █░░░░ 1.0 / 5.0 | G19: Difference: | H19: =H18-E2 -> -38.321687 | I19: Difference: | J19: =J18-E2 -> -47.523844
A20: OVERALL SCORE | B20: =Analysis!D52 -> 3.0583333 | C20: / 5.0 | G20: Margin of Safety: | H20: =IFERROR((H18-E2)/H18,0) -> -0.44921397 | I20: Margin of Safety: | J20: =IFERROR((J18-E2)/J18,0) -> -0.62444153
G21: Graham Number | H21: =IF(Valuation!F108="On",Valuation!D112,"Off") -> 28.608299 | I21: DDM | J21: =IF(Valuation!F114="On",Valuation!D119,"Off") -> -9.4198386 | K21: Mean | L21: =Valuation!B159 -> 96.290976
G22: Difference: | H22: =H21-E2 -> -95.021701 | I22: Difference: | J22: =J21-E2 -> -133.04984 | K22: Median | L22: =Valuation!B160 -> 87.904047
G23: Margin of Safety: | H23: =IFERROR((H21-E2)/H21,0) -> -3.3214734 | I23: Margin of Safety: | J23: =IFERROR((J21-E2)/J21,0) -> 14.124429 | K23: Std Deviation | L23: =Valuation!B161 -> 49.228425
G24: ABV | H24: =IF(Valuation!F121="On",Valuation!D124,"Off") -> 12.417976 | I24: RIM | J24: =IF(Valuation!F126="On",Valuation!D130,"Off") -> 31.684029 | K24: 10th Percentile | L24: =Valuation!B162 -> 36.885697
G25: Difference: | H25: =H24-E2 -> -111.21202 | I25: Difference: | J25: =J24-E2 -> -91.945971 | K25: 25th Percentile | L25: =Valuation!B163 -> 55.645214
G26: Margin of Safety: | H26: =IFERROR((H24-E2)/H24,0) -> -8.955729 | I26: Margin of Safety: | J26: =IFERROR((J24-E2)/J24,0) -> -2.9019659 | K26: 75th Percentile | L26: =Valuation!B164 -> 129.02101
G27: MARKET-IMPLIED ASSUMPTIONS (REVERSE DCF) | K27: 90th Percentile | L27: =Valuation!B165 -> 167.96064
G28: Assumption | H28: Base Case | I28: Market-Implied | J28: % Change | K28: Min | L28: =Valuation!B166 -> 24.364502
G29: Terminal Growth (g) | H29: =Valuation!I14 -> 0.025 | I29: =Valuation!W9 -> 0.036109847 | J29: =IFERROR((I29-H29)/H29,"N/A") -> 0.44439387 | K29: Max | L29: =Valuation!B167 -> 223.4485
G30: WACC | H30: =Valuation!I13 -> 0.06 | I30: =Valuation!W20 -> 0.049875913 | J30: =IFERROR((I30-H30)/H30,"N/A") -> -0.16873479 | K30: Prob > Current Price | L30: =Valuation!B169 -> 0.27672956
G31: Revenue Growth | H31: =Valuation!I2 -> 0.1 | I31: =Valuation!W36 -> 0.19823985 | J31: =IFERROR((I31-H31)/H31,"N/A") -> 0.98239851 | K31: 80% CI Low | L31: =Valuation!B170 -> 36.885697
G32: Blended Intrinsic Value | H32: =Valuation!W47 -> 122.18853 | I32: vs Market: | J32: =Valuation!W48 -> -0.01165953 | K32: 80% CI High | L32: =Valuation!B171 -> 167.96064
A47: HISTORICAL FINANCIAL TRENDS
A48: Year | B48: ='Data Schema'!F1 -> 2023 | C48: ='Data Schema'!E1 -> 2024 | D48: ='Data Schema'!D1 -> 2025 | E48: ='Data Schema'!C1 -> 2026 | F48: TTM
A49: Revenue | B49: ='Data Schema'!F3 -> 611289000 | C49: ='Data Schema'!E3 -> 648125000 | D49: ='Data Schema'!D3 -> 680985000 | E49: ='Data Schema'!C3 -> 713163000 | F49: ='Data Schema'!B3 -> 713163000
A50: Net Income | B50: ='Data Schema'!F13 -> 11680000 | C50: ='Data Schema'!E13 -> 15511000 | D50: ='Data Schema'!D13 -> 19436000 | E50: ='Data Schema'!C13 -> 21893000 | F50: ='Data Schema'!B13 -> 21893000
A51: Op Income | B51: ='Data Schema'!F14 -> 19144000 | C51: ='Data Schema'!E14 -> 24531000 | D51: ='Data Schema'!D14 -> 29037000 | E51: ='Data Schema'!C14 -> 32268000 | F51: ='Data Schema'!B14 -> 32268000
A52: FCFF | B52: ='Data Schema'!B40 -> 14923000 | C52: ='Data Schema'!C40 -> 14923000 | D52: ='Data Schema'!D40 -> 12660000 | E52: ='Data Schema'!E40 -> 15120000 | F52: ='Data Schema'!F40 -> 11984000
A53: Gross Margin | B53: =Calculations!G37 -> 0.24140464 | C53: =Calculations!F37 -> 0.24375391 | D53: =Calculations!E37 -> 0.24851061 | E53: =Calculations!D37 -> 0.249267 | F53: =Calculations!C37 -> N/A
A54: Op Margin | B54: =Calculations!G38 -> 0.031317429 | C54: =Calculations!F38 -> 0.03784918 | D54: =Calculations!E38 -> 0.042639706 | E54: =Calculations!D38 -> 0.045246318 | F54: =Calculations!C38 -> N/A
...

Sheet Analysis
A1: Financial Analysis & Ratings
A2: Company: | B2: ='Raw Data Pasting'!V3 -> WMT
A3: Date: | B3: As of Latest Filing
A5: Profitability Metrics | B5: Current Value | C5: Historical Avg | D5: Textbook Rating | E5: Trend Rating | F5: Final Rating
A6: Gross Margin | B6: =Calculations!D37 -> 0.249267 | C6: =Calculations!H37 -> 0.24573404 | D6: =IFERROR(IF(B6>=0.4,5,IF(B6>=0.3,4,IF(B6>=0.2,3,IF(B6>=0.1,2,1)))),"N/A") -> 3 | E6: =IFERROR(IF((B6-C6)/ABS(C6)>=0.1,5,IF((B6-C6)/ABS(C6)>=0.05,4,IF((B6-C6)/ABS(C6)>=-0.05,3,IF((B6-C6)/ABS(C6)>=-0.1,2,1)))),"N/A") -> 3 | F6: =IFERROR(ROUND(AVERAGE(D6,E6),1),"N/A") -> 3
A7: Operating Margin | B7: =Calculations!D38 -> 0.045246318 | C7: =Calculations!H38 -> 0.039263158 | D7: =IFERROR(IF(B7>=0.15,5,IF(B7>=0.1,4,IF(B7>=0.05,3,IF(B7>=0.02,2,1)))),"N/A") -> 2 | E7: =IFERROR(IF((B7-C7)/ABS(C7)>=0.1,5,IF((B7-C7)/ABS(C7)>=0.05,4,IF((B7-C7)/ABS(C7)>=-0.05,3,IF((B7-C7)/ABS(C7)>=-0.1,2,1)))),"N/A") -> 5 | F7: =IFERROR(ROUND(AVERAGE(D7,E7),1),"N/A") -> 3.5
A8: Net Margin | B8: =Calculations!D39 -> 0.030698452 | C8: =Calculations!H39 -> 0.025569685 | D8: =IFERROR(IF(B8>=0.1,5,IF(B8>=0.05,4,IF(B8>=0.02,3,IF(B8>=0,2,1)))),"N/A") -> 3 | E8: =IFERROR(IF((B8-C8)/ABS(C8)>=0.1,5,IF((B8-C8)/ABS(C8)>=0.05,4,IF((B8-C8)/ABS(C8)>=-0.05,3,IF((B8-C8)/ABS(C8)>=-0.1,2,1)))),"N/A") -> 5 | F8: =IFERROR(ROUND(AVERAGE(D8,E8),1),"N/A") -> 4
A9: ROE | B9: =Calculations!D41 -> 0.20618761 | C9: =Calculations!H41 -> 0.17886496 | D9: =IFERROR(IF(B9>=0.2,5,IF(B9>=0.15,4,IF(B9>=0.1,3,IF(B9>=0.05,2,1)))),"N/A") -> 5 | E9: =IFERROR(IF((B9-C9)/ABS(C9)>=0.1,5,IF((B9-C9)/ABS(C9)>=0.05,4,IF((B9-C9)/ABS(C9)>=-0.05,3,IF((B9-C9)/ABS(C9)>=-0.1,2,1)))),"N/A") -> 5 | F9: =IFERROR(ROUND(AVERAGE(D9,E9),1),"N/A") -> 5
A10: ROA | B10: =Calculations!D40 -> 0.076907134 | C10: =Calculations!H40 -> 0.065226574 | D10: =IFERROR(IF(B10>=0.1,5,IF(B10>=0.05,4,IF(B10>=0.02,3,IF(B10>=0,2,1)))),"N/A") -> 4 | E10: =IFERROR(IF((B10-C10)/ABS(C10)>=0.1,5,IF((B10-C10)/ABS(C10)>=0.05,4,IF((B10-C10)/ABS(C10)>=-0.05,3,IF((B10-C10)/ABS(C10)>=-0.1,2,1)))),"N/A") -> 5 | F10: =IFERROR(ROUND(AVERAGE(D10,E10),1),"N/A") -> 4.5
A11: ROIC | B11: =Calculations!D61 -> 0.15001864 | C11: =Calculations!H61 -> 0.13069707 | D11: =IFERROR(IF(B11>=0.15,5,IF(B11>=0.1,4,IF(B11>=0.05,3,IF(B11>=0.02,2,1)))),"N/A") -> 5 | E11: =IFERROR(IF((B11-C11)/ABS(C11)>=0.1,5,IF((B11-C11)/ABS(C11)>=0.05,4,IF((B11-C11)/ABS(C11)>=-0.05,3,IF((B11-C11)/ABS(C11)>=-0.1,2,1)))),"N/A") -> 5 | F11: =IFERROR(ROUND(AVERAGE(D11,E11),1),"N/A") -> 5
A12: Profitability Score | F12: =IFERROR(AVERAGE(F6:F11),"N/A") -> 4.1666667
A14: Liquidity Metrics | B14: Current Value | C14: Historical Avg | D14: Textbook Rating | E14: Trend Rating | F14: Final Rating
A15: Current Ratio | B15: =Calculations!D31 -> 0.78975332 | C15: =Calculations!H31 -> 0.81621856 | D15: =IFERROR(IF(B15>=2,5,IF(B15>=1.5,4,IF(B15>=1,3,IF(B15>=0.5,2,1)))),"N/A") -> 2 | E15: =IFERROR(IF((B15-C15)/ABS(C15)>=0.1,5,IF((B15-C15)/ABS(C15)>=0.05,4,IF((B15-C15)/ABS(C15)>=-0.05,3,IF((B15-C15)/ABS(C15)>=-0.1,2,1)))),"N/A") -> 3 | F15: =IFERROR(ROUND(AVERAGE(D15,E15),1),"N/A") -> 2.5
A16: Quick Ratio | B16: =Calculations!D32 -> 0.20377039 | C16: =Calculations!H32 -> 0.19553852 | D16: =IFERROR(IF(B16>=1.5,5,IF(B16>=1,4,IF(B16>=0.75,3,IF(B16>=0.5,2,1)))),"N/A") -> 1 | E16: =IFERROR(IF((B16-C16)/ABS(C16)>=0.1,5,IF((B16-C16)/ABS(C16)>=0.05,4,IF((B16-C16)/ABS(C16)>=-0.05,3,IF((B16-C16)/ABS(C16)>=-0.1,2,1)))),"N/A") -> 3 | F16: =IFERROR(ROUND(AVERAGE(D16,E16),1),"N/A") -> 2
A17: Cash Ratio | B17: =Calculations!D63 -> 0.09981483 | C17: =Calculations!H63 -> 0.098424525 | D17: =IFERROR(IF(B17>=1,5,IF(B17>=0.5,4,IF(B17>=0.25,3,IF(B17>=0.1,2,1)))),"N/A") -> 1 | E17: =IFERROR(IF((B17-C17)/ABS(C17)>=0.1,5,IF((B17-C17)/ABS(C17)>=0.05,4,IF((B17-C17)/ABS(C17)>=-0.05,3,IF((B17-C17)/ABS(C17)>=-0.1,2,1)))),"N/A") -> 3 | F17: =IFERROR(ROUND(AVERAGE(D17,E17),1),"N/A") -> 2
A18: Liquidity Score | F18: =IFERROR(AVERAGE(F15:F17),"N/A") -> 2.1666667
A20: Leverage/Risk Metrics | B20: Current Value | C20: Historical Avg | D20: Textbook Rating | E20: Trend Rating | F20: Final Rating
A21: Debt-to-Equity | B21: =Calculations!D33 -> 0.63189866 | C21: =Calculations!H33 -> 0.65645729 | D21: =IFERROR(IF(B21<=0.5,5,IF(B21<=1,4,IF(B21<=2,3,IF(B21<=3,2,1)))),"N/A") -> 4 | E21: =IFERROR(IF((C21-B21)/ABS(C21)>=0.1,5,IF((C21-B21)/ABS(C21)>=0.05,4,IF((C21-B21)/ABS(C21)>=-0.05,3,IF((C21-B21)/ABS(C21)>=-0.1,2,1)))),"N/A") -> 3 | F21: =IFERROR(ROUND(AVERAGE(D21,E21),1),"N/A") -> 3.5
A22: Debt-to-Assets | B22: =Calculations!D34 -> 0.23569562 | C22: =Calculations!H34 -> 0.23785286 | D22: =IFERROR(IF(B22<=0.3,5,IF(B22<=0.5,4,IF(B22<=0.7,3,IF(B22<=0.9,2,1)))),"N/A") -> 5 | E22: =IFERROR(IF((C22-B22)/ABS(C22)>=0.1,5,IF((C22-B22)/ABS(C22)>=0.05,4,IF((C22-B22)/ABS(C22)>=-0.05,3,IF((C22-B22)/ABS(C22)>=-0.1,2,1)))),"N/A") -> 3 | F22: =IFERROR(ROUND(AVERAGE(D22,E22),1),"N/A") -> 4
A23: Interest Coverage | B23: =Calculations!D35 -> 11.528403 | C23: =Calculations!H35 -> 10.710998 | D23: =IFERROR(IF(B23>=8,5,IF(B23>=5,4,IF(B23>=2.5,3,IF(B23>=1,2,1)))),"N/A") -> 5 | E23: =IFERROR(IF((B23-C23)/ABS(C23)>=0.1,5,IF((B23-C23)/ABS(C23)>=0.05,4,IF((B23-C23)/ABS(C23)>=-0.05,3,IF((B23-C23)/ABS(C23)>=-0.1,2,1)))),"N/A") -> 4 | F23: =IFERROR(ROUND(AVERAGE(D23,E23),1),"N/A") -> 4.5
A24: Leverage Score | F24: =IFERROR(AVERAGE(F21:F23),"N/A") -> 4
A26: Efficiency Metrics | B26: Current Value | C26: Historical Avg | D26: Textbook Rating | E26: Trend Rating | F26: Final Rating
A27: Asset Turnover | B27: =Calculations!D45 -> 2.6147562 | C27: =Calculations!H45 -> 2.7140206 | D27: =IFERROR(IF(B27>=2,5,IF(B27>=1.5,4,IF(B27>=1,3,IF(B27>=0.5,2,1)))),"N/A") -> 5 | E27: =IFERROR(IF((B27-C27)/ABS(C27)>=0.1,5,IF((B27-C27)/ABS(C27)>=0.05,4,IF((B27-C27)/ABS(C27)>=-0.05,3,IF((B27-C27)/ABS(C27)>=-0.1,2,1)))),"N/A") -> 3 | F27: =IFERROR(ROUND(AVERAGE(D27,E27),1),"N/A") -> 4
A28: Inventory Turnover | B28: =Calculations!D46 -> 9.2881182 | C28: =Calculations!H46 -> 10.917242 | D28: =IFERROR(IF(B28>=10,5,IF(B28>=7,4,IF(B28>=5,3,IF(B28>=3,2,1)))),"N/A") -> 4 | E28: =IFERROR(IF((B28-C28)/ABS(C28)>=0.1,5,IF((B28-C28)/ABS(C28)>=0.05,4,IF((B28-C28)/ABS(C28)>=-0.05,3,IF((B28-C28)/ABS(C28)>=-0.1,2,1)))),"N/A") -> 1 | F28: =IFERROR(ROUND(AVERAGE(D28,E28),1),"N/A") -> 2.5
A29: Efficiency Score | F29: =IFERROR(AVERAGE(F27:F28),"N/A") -> 3.25
A31: Growth Metrics | B31: Current Value | C31: Historical Avg | D31: Textbook Rating | E31: Trend Rating | F31: Final Rating
A32: Revenue Growth (YoY) | B32: =Calculations!D54 -> 0.047252142 | C32: =Calculations!H54 -> 0.052737263 | D32: =IFERROR(IF(B32>=0.2,5,IF(B32>=0.1,4,IF(B32>=0.05,3,IF(B32>=0,2,1)))),"N/A") -> 2 | E32: =IFERROR(IF((B32-C32)/ABS(C32)>=0.1,5,IF((B32-C32)/ABS(C32)>=0.05,4,IF((B32-C32)/ABS(C32)>=-0.05,3,IF((B32-C32)/ABS(C32)>=-0.1,2,1)))),"N/A") -> 1 | F32: =IFERROR(ROUND(AVERAGE(D32,E32),1),"N/A") -> 1.5
A33: Revenue CAGR (3Y) | B33: =Calculations!C64 -> 0.052722909 | C33: =Calculations!C64 -> 0.052722909 | D33: =IFERROR(IF(B33>=0.2,5,IF(B33>=0.1,4,IF(B33>=0.05,3,IF(B33>=0,2,1)))),"N/A") -> 3 | E33: =IFERROR(IF((B33-C33)/ABS(C33)>=0.1,5,IF((B33-C33)/ABS(C33)>=0.05,4,IF((B33-C33)/ABS(C33)>=-0.05,3,IF((B33-C33)/ABS(C33)>=-0.1,2,1)))),"N/A") -> 3 | F33: =IFERROR(ROUND(AVERAGE(D33,E33),1),"N/A") -> 3
A34: Earnings Growth | B34: =Calculations!D55 -> 0.1264149 | C34: =Calculations!H55 -> 0.23581923 | D34: =IFERROR(IF(B34>=0.2,5,IF(B34>=0.1,4,IF(B34>=0.05,3,IF(B34>=0,2,1)))),"N/A") -> 4 | E34: =IFERROR(IF((B34-C34)/ABS(C34)>=0.1,5,IF((B34-C34)/ABS(C34)>=0.05,4,IF((B34-C34)/ABS(C34)>=-0.05,3,IF((B34-C34)/ABS(C34)>=-0.1,2,1)))),"N/A") -> 1 | F34: =IFERROR(ROUND(AVERAGE(D34,E34),1),"N/A") -> 2.5
A35: Growth Score | F35: =IFERROR(AVERAGE(F32:F34),"N/A") -> 2.3333333
A37: Valuation vs Peers | B37: Company Value | C37: Peer Avg | D37: Ratio (Co/Peer) | E37: Relative Rating
A38: P/E | B38: ='Data Schema'!B44 -> 43.6 | C38: ='Data Schema'!F44 -> 27.556667 | D38: =IFERROR(B38/C38,"N/A") -> 1.5821943 | E38: =IFERROR(IF(D38<=0.5,5,IF(D38<=0.75,4,IF(D38<=1,3,IF(D38<=1.25,2,1)))),"N/A") -> 1
A39: P/B | B39: ='Data Schema'!B47 -> 9.53 | C39: ='Data Schema'!F47 -> 6.61 | D39: =IFERROR(B39/C39,"N/A") -> 1.4417549 | E39: =IFERROR(IF(D39<=0.5,5,IF(D39<=0.75,4,IF(D39<=1,3,IF(D39<=1.25,2,1)))),"N/A") -> 1
A40: P/S | B40: ='Data Schema'!B48 -> 1.34 | C40: ='Data Schema'!F48 -> 0.88 | D40: =IFERROR(B40/C40,"N/A") -> 1.5227273 | E40: =IFERROR(IF(D40<=0.5,5,IF(D40<=0.75,4,IF(D40<=1,3,IF(D40<=1.25,2,1)))),"N/A") -> 1
A41: EV/EBITDA | B41: ='Data Schema'!B49 -> 21.63 | C41: ='Data Schema'!F49 -> 16.943333 | D41: =IFERROR(B41/C41,"N/A") -> 1.2766083 | E41: =IFERROR(IF(D41<=0.5,5,IF(D41<=0.75,4,IF(D41<=1,3,IF(D41<=1.25,2,1)))),"N/A") -> 1
A42: P/FCF | B42: ='Data Schema'!B46 -> 63.98 | C42: ='Data Schema'!F46 -> 25.733333 | D42: =IFERROR(B42/C42,"N/A") -> 2.4862694 | E42: =IFERROR(IF(D42<=0.5,5,IF(D42<=0.75,4,IF(D42<=1,3,IF(D42<=1.25,2,1)))),"N/A") -> 1
A43: Valuation Score | E43: =IFERROR(AVERAGE(E38:E42),"N/A") -> 1
A45: Overall Score Summary | B45: Category Score | C45: Weight | D45: Weighted Score
A46: Profitability | B46: =F12 -> 4.1666667 | C46: 0.25 | D46: =IFERROR(B46*C46,0) -> 1.0416667
A47: Liquidity | B47: =F18 -> 2.1666667 | C47: 0.15 | D47: =IFERROR(B47*C47,0) -> 0.325
...

Sheet Valuation
A1: Base Case DCF | H1: Assumptions | I1: Value | J1: Selector Switch | K1: Manual Input | L1: Historical Average | M1: =Calculations!D1 -> 2026 | N1: =Calculations!E1 -> 2025 | O1: =Calculations!F1 -> 2024 | P1: =Calculations!G1 -> 2023 | R1: REVERSE DCF CALCULATIONS
A2: Forecasted Data all numbers in thousands | B2: ='Data Schema'!$C$1+1 -> 2027 | C2: ='Data Schema'!$C$1+2 -> 2028 | D2: ='Data Schema'!$C$1+3 -> 2029 | E2: ='Data Schema'!$C$1+4 -> 2030 | F2: ='Data Schema'!$C$1+5 -> 2031 | H2: Revenue Growth Rate | I2: {=_xlfn.SWITCH(J2,"Manual",K2,"Average",L2,"Manual +2.5%",K2*1.025, "Manual +5%",K2*1.05, "Manual +10%",K2*1.1, "Manual -2.5%",K2*0.975,"Manual -5%",K2*0.95, "Manual -10%",K2*0.9)} -> 0.1 | J2: Manual | K2: 0.1 | L2: =Calculations!H54 -> 0.052737263 | M2: =Calculations!D54 -> 0.047252142 | N2: =Calculations!E54 -> 0.050700096 | O2: =Calculations!F54 -> 0.06025955 | P2: =Calculations!G54 -> N/A
A3: Total Revenue (Net Sales)* | B3: ='Data Schema'!C3*(1+I2) -> 7.844793e+08 | C3: =B3*(1+$I$2) -> 8.6292723e+08 | D3: =C3*(1+$I$2) -> 9.4921995e+08 | E3: =D3*(1+$I$2) -> 1.0441419e+09 | F3: =E3*(1+$I$2) -> 1.1485561e+09 | H3: Expense Ratios (% of Rev) | R3: Target Enterprise Value | W3: =F29*F27+F25-F24 -> 1048127860
A4: less COGS/ Cost of Revenue | B4: =B3*$I$4 -> 5.8835948e+08 | C4: =C3*$I$4 -> 6.4719542e+08 | D4: =D3*$I$4 -> 7.1191496e+08 | E4: =E3*$I$4 -> 7.8310646e+08 | F4: =F3*$I$4 -> 8.6141711e+08 | H4: COGS as % of Revenue | I4: {=_xlfn.SWITCH(J4,"Manual",K4,"Average",L4,"Manual +2.5%",K4*1.025, "Manual +5%",K4*1.05, "Manual +10%",K4*1.1, "Manual -2.5%",K4*0.975,"Manual -5%",K4*0.95, "Manual -10%",K4*0.9)} -> 0.75 | J4: Manual | K4: 0.75 | L4: =Calculations!H9 -> 0.75426596 | M4: =Calculations!D9 -> 0.750733 | N4: =Calculations!E9 -> 0.75148939 | O4: =Calculations!F9 -> 0.75624609 | P4: =Calculations!G9 -> 0.75859536
A5: Gross Profit | B5: =B3-B4 -> 196119825 | C5: =C3-C4 -> 2.1573181e+08 | D5: =D3-D4 -> 2.3730499e+08 | E5: =E3-E4 -> 2.6103549e+08 | F5: =F3-F4 -> 2.8713904e+08 | H5: OpEx as % of Revenue | I5: {=_xlfn.SWITCH(J5,"Manual",K5,"Average",L5,"Manual +2.5%",K5*1.025, "Manual +5%",K5*1.05, "Manual +10%",K5*1.1, "Manual -2.5%",K5*0.975,"Manual -5%",K5*0.95, "Manual -10%",K5*0.9)} -> 0.207 | J5: Manual | K5: 0.207 | L5: =Calculations!H10 -> 0.20573099 | M5: =Calculations!D10 -> 0.20744626 | N5: =Calculations!E10 -> 0.20541422 | O5: =Calculations!F10 -> 0.20207676 | P5: =Calculations!G10 -> 0.20798673 | R5: Scenario 1: Implied Terminal Growth (g) — Analytical
A6: less OpEx | B6: =B3*$I$5 -> 1.6238722e+08 | C6: =C3*$I$5 -> 1.7862594e+08 | D6: =D3*$I$5 -> 1.9648853e+08 | E6: =E3*$I$5 -> 2.1613738e+08 | F6: =F3*$I$5 -> 2.3775112e+08 | H6: D&A as % of Revenue | I6: {=_xlfn.SWITCH(J6,"Manual",K6,"Average",L6,"Manual +2.5%",K6*1.025, "Manual +5%",K6*1.05, "Manual +10%",K6*1.1, "Manual -2.5%",K6*0.975,"Manual -5%",K6*0.95, "Manual -10%",K6*0.9)} -> 0.025 | J6: Manual | K6: 0.025 | L6: =Calculations!H11 -> 0.018789694 | M6: =Calculations!D11 -> 0.019915503 | N6: =Calculations!E11 -> 0.019050346 | O6: =Calculations!F11 -> 0.018288139 | P6: =Calculations!G11 -> 0.017904788 | R6: Sum of PV of FCFFs (from model) | W6: =SUM(B17:F17) -> 1.0148278e+08
A7: Operating Income (EBIT) | B7: =B5-B6 -> 33732610 | C7: =C5-C6 -> 37105871 | D7: =D5-D6 -> 40816458 | E7: =E5-E6 -> 44898104 | F7: =F5-F6 -> 49387914 | H7: Capital Structure Assumptions | R7: Required PV of Terminal Value | W7: =W3-W6 -> 9.4664508e+08
A8: less Interest Expense | B8: =$I$8*$I$9 -> 2400000 | C8: =$I$8*$I$9 -> 2400000 | D8: =$I$8*$I$9 -> 2400000 | E8: =$I$8*$I$9 -> 2400000 | F8: =$I$8*$I$9 -> 2400000 | H8: Total Debt | I8: {=_xlfn.SWITCH(J8,"Manual",K8,"Average",L8,"Manual +2.5%",K8*1.025, "Manual +5%",K8*1.05, "Manual +10%",K8*1.1, "Manual -2.5%",K8*0.975,"Manual -5%",K8*0.95, "Manual -10%",K8*0.9)} -> 60000000 | J8: Manual | K8: 60000000 | L8: =AVERAGE('Data Schema'!C31:F31) -> 61863250 | M8: ='Data Schema'!C31 -> 67095000 | N8: ='Data Schema'!D31 -> 60114000 | O8: ='Data Schema'!E31 -> 61321000 | P8: ='Data Schema'!F31 -> 58923000 | R8: Required Terminal Value | W8: =W7*(1+I13)^5 -> 1.2668247e+09
A9: EBT (Pretax Income) | B9: =B7-B8 -> 31332610 | C9: =C7-C8 -> 34705871 | D9: =D7-D8 -> 38416458 | E9: =E7-E8 -> 42498104 | F9: =F7-F8 -> 46987914 | H9: Interest Rate | I9: {=_xlfn.SWITCH(J9,"Manual",K9,"Average",L9,"Manual +2.5%",K9*1.025, "Manual +5%",K9*1.05, "Manual +10%",K9*1.1, "Manual -2.5%",K9*0.975,"Manual -5%",K9*0.95, "Manual -10%",K9*0.9)} -> 0.04 | J9: Manual | K9: 0.04 | L9: =Calculations!H8 -> 0.041741426 | M9: =Calculations!D8 -> 0.041716968 | N9: =Calculations!E8 -> 0.045380444 | O9: =Calculations!F8 -> 0.043753363 | P9: =Calculations!G8 -> 0.03611493 | R9: Implied g | W9: =(W8*I13-F16)/(W8+F16) -> 0.036109847
A10: less Income Tax Expense/Tax Provision | B10: =B9*$I$10 -> 7833152.5 | C10: =C9*$I$10 -> 8676467.7 | D10: =D9*$I$10 -> 9604114.5 | E10: =E9*$I$10 -> 10624526 | F10: =F9*$I$10 -> 11746979 | H10: Effective Tax Rate (T) | I10: {=_xlfn.SWITCH(J10,"Manual",K10,"Average",L10,"Manual +2.5%",K10*1.025, "Manual +5%",K10*1.05, "Manual +10%",K10*1.1, "Manual -2.5%",K10*0.975,"Manual -5%",K10*0.95, "Manual -10%",K10*0.9)} -> 0.25 | J10: Manual | K10: 0.25 | L10: =Calculations!H3 -> 0.26745641 | M10: =Calculations!D3 -> 0.24429061 | N10: =Calculations!E3 -> 0.23383633 | O10: =Calculations!F3 -> 0.25530941 | P10: =Calculations!G3 -> 0.33638928 | R10: Base g | W10: =I14 -> 0.025
A11: Net Income (Common Stockholders) | B11: =B9-B10 -> 23499457 | C11: =C9-C10 -> 26029403 | D11: =D9-D10 -> 28812343 | E11: =E9-E10 -> 31873578 | F11: =F9-F10 -> 35240936 | H11: CapEx as % of Revenue | I11: {=_xlfn.SWITCH(J11,"Manual",K11,"Average",L11,"Manual +2.5%",K11*1.025, "Manual +5%",K11*1.05, "Manual +10%",K11*1.1, "Manual -2.5%",K11*0.975,"Manual -5%",K11*0.95, "Manual -10%",K11*0.9)} -> 0.03 | J11: Manual | K11: 0.03 | L11: =Calculations!H12 -> 0.032912833 | M11: =Calculations!D12 -> 0.037357519 | N11: =Calculations!E12 -> 0.034924411 | O11: =Calculations!F12 -> 0.03179325 | P11: =Calculations!G12 -> 0.027576155 | R11: Δg (Implied − Base) | W11: =W9-W10 -> 0.011109847 | X11: =(W9/(W10))-1 -> 0.44439387
A12: add Interest expense | B12: =B8*(1-$I$10) -> 1800000 | C12: =C8*(1-$I$10) -> 1800000 | D12: =D8*(1-$I$10) -> 1800000 | E12: =E8*(1-$I$10) -> 1800000 | F12: =F8*(1-$I$10) -> 1800000 | H12: Change in Non-Cash WC (ΔWC) | I12: {=_xlfn.SWITCH(J12,"Manual",K12,"Average",L12,"Manual +2.5%",K12*1.025, "Manual +5%",K12*1.05, "Manual +10%",K12*1.1, "Manual -2.5%",K12*0.975,"Manual -5%",K12*0.95, "Manual -10%",K12*0.9)} -> 0.02 | J12: Manual | K12: 0.02 | L12: use 2-5% of Rev Growth or higher (depends on industry)
A13: add D&A | B13: =B3*$I$6 -> 19611983 | C13: =C3*$I$6 -> 21573181 | D13: =D3*$I$6 -> 23730499 | E13: =E3*$I$6 -> 26103549 | F13: =F3*$I$6 -> 28713904 | H13: WACC | I13: {=_xlfn.SWITCH(J13,"Manual",K13,"Calculated",N13,"Manual +2.5%",K13*1.025, "Manual +5%",K13*1.05, "Manual +10%",K13*1.1, "Manual -2.5%",K13*0.975,"Manual -5%",K13*0.95, "Manual -10%",K13*0.9)} -> 0.06 | J13: Manual | K13: 0.06 | L13: Imported from Calculations tab: | N13: =Calculations!C23 -> 0.096068137 | R13: Scenario 2: Implied WACC — Binary Search (20 Iterations)
A14: less Change in Non-Cash WC | B14: =(B3-'Data Schema'!C3)*$I$12 -> 1426326 | C14: =(C3-B3)*$I$12 -> 1568958.6 | D14: =(D3-C3)*$I$12 -> 1725854.5 | E14: =(E3-D3)*$I$12 -> 1898439.9 | F14: =(F3-E3)*$I$12 -> 2088283.9 | H14: Terminal Growth (g) | I14: {=_xlfn.SWITCH(J14,"Manual",K14,"Calculated",N14,"Manual +2.5%",K14*1.025, "Manual +5%",K14*1.05, "Manual +10%",K14*1.1, "Manual -2.5%",K14*0.975,"Manual -5%",K14*0.95, "Manual -10%",K14*0.9)} -> 0.025 | J14: Calculated | K14: 0.03 | L14: Imported from Calculations tab: | N14: =Calculations!C28 -> 0.025 | R14: Iteration | S14: Start | T14: 1 | U14: 2 | V14: 3 | W14: 4 | X14: 5 | Y14: 6 | Z14: 7 | AA14: 8 | AB14: 9 | AC14: 10 | AD14: 11 | AE14: 12 | AF14: 13 | AG14: 14 | AH14: 15 | AI14: 16 | AJ14: 17 | AK14: 18 | AL14: 19 | AM14: 20
A15: less Capital Expenditures (CapEx) | B15: =B3*$I$11 -> 23534379 | C15: =C3*$I$11 -> 25887817 | D15: =D3*$I$11 -> 28476599 | E15: =E3*$I$11 -> 31324258 | F15: =F3*$I$11 -> 34456684 | H15: Capital Structure Assumptions | R15: Low | S15: 0.01 | T15: =IF(S18>$W$3,S17,S15) -> 0.01 | U15: =IF(T18>$W$3,T17,T15) -> 0.01 | V15: =IF(U18>$W$3,U17,U15) -> 0.04625 | W15: =IF(V18>$W$3,V17,V15) -> 0.04625 | X15: =IF(W18>$W$3,W17,W15) -> 0.04625 | Y15: =IF(X18>$W$3,X17,X15) -> 0.04625 | Z15: =IF(Y18>$W$3,Y17,Y15) -> 0.048515625 | AA15: =IF(Z18>$W$3,Z17,Z15) -> 0.049648438 | ... AM15: =IF(AL18>$W$3,AL17,AL15) -> 0.049875774
A16: Free Cash Flow to the Firm (FCFF) | B16: =B11+B12+B13-B14-B15 -> 19950735 | C16: =C11+C12+C13-C14-C15 -> 21945808 | D16: =D11+D12+D13-D14-D15 -> 24140389 | E16: =E11+E12+E13-E14-E15 -> 26554428 | F16: =F11+F12+F13-F14-F15 -> 29209871 | H16: Operating Margin | I16: {=_xlfn.SWITCH(J16,"Forecasted",F18,"Manual",K16,"Average",L16,"Manual +2.5%",K16*1.025, "Manual +5%",K16*1.05, "Manual +10%",K16*1.1, "Manual -2.5%",K16*0.975,"Manual -5%",K16*0.95, "Manual -10%",K16*0.9)} -> 0.043 | J16: Forecasted | K16: 0.03 | L16: =Calculations!H13 -> 0.025569685 | M16: =Calculations!D13 -> 0.030698452 | N16: =Calculations!E13 -> 0.02854101 | O16: =Calculations!F13 -> 0.023932112 | P16: =Calculations!G13 -> 0.019107165 | R16: High | S16: 0.3 | T16: =IF(S18>$W$3,S16,S17) -> 0.155 | U16: =IF(T18>$W$3,T16,T17) -> 0.0825 | V16: =IF(U18>$W$3,U16,U17) -> 0.0825 | W16: =IF(V18>$W$3,V16,V17) -> 0.064375 | X16: =IF(W18>$W$3,W16,W17) -> 0.0553125 | Y16: =IF(X18>$W$3,X16,X17) -> 0.05078125 | Z16: =IF(Y18>$W$3,Y16,Y17) -> 0.05078125 | AA16: =IF(Z18>$W$3,Z16,Z17) -> 0.05078125 | ... AM16: =IF(AL18>$W$3,AL16,AL17) -> 0.049876051
A17: PV of FCFF [FCFFt / (1+WACC)t] | B17: =B16/(1+$I$13)^1 -> 18821448 | C17: =C16/(1+$I$13)^2 -> 19531691 | D17: =D16/(1+$I$13)^3 -> 20268736 | E17: =E16/(1+$I$13)^4 -> 21033594 | F17: =F16/(1+$I$13)^5 -> 21827315 | R17: Mid (Trial WACC) | S17: =(S15+S16)/2 -> 0.155 | T17: =(T15+T16)/2 -> 0.0825 | U17: =(U15+U16)/2 -> 0.04625 | V17: =(V15+V16)/2 -> 0.064375 | W17: =(W15+W16)/2 -> 0.0553125 | X17: =(X15+X16)/2 -> 0.05078125 | Y17: =(Y15+Y16)/2 -> 0.048515625 | Z17: =(Z15+Z16)/2 -> 0.049648438 | ... AM17: =(AM15+AM16)/2 -> 0.049875913
E18: Operating Margin | F18: =(F7/F3) -> 0.043 | R18: EV at Trial WACC | S18: =$B$16/(1+S17)^1+$C$16/(1+S17)^2+$D$16/(1+S17)^3+$E$16/(1+S17)^4+$F$16/(1+S17)^5+$F$16*(1+$I$14)/((S17-$I$14)*(1+S17)^5) -> 1.9057086e+08 | T18: =$B$16/(1+T17)^1+$C$16/(1+T17)^2+$D$16/(1+T17)^3+$E$16/(1+T17)^4+$F$16/(1+T17)^5+$F$16*(1+$I$14)/((T17-$I$14)*(1+T17)^5) -> 4.4548408e+08 | U18: =$B$16/(1+U17)^1+$C$16/(1+U17)^2+$D$16/(1+U17)^3+$E$16/(1+U17)^4+$F$16/(1+U17)^5+$F$16*(1+$I$14)/((U17-$I$14)*(1+U17)^5) -> 1.2295297e+09 | V18: =$B$16/(1+V17)^1+$C$16/(1+V17)^2+$D$16/(1+V17)^3+$E$16/(1+V17)^4+$F$16/(1+V17)^5+$F$16*(1+$I$14)/((V17-$I$14)*(1+V17)^5) -> 6.5682868e+08 | W18: =$B$16/(1+W17)^1+$C$16/(1+W17)^2+$D$16/(1+W17)^3+$E$16/(1+W17)^4+$F$16/(1+W17)^5+$F$16*(1+$I$14)/((W17-$I$14)*(1+W17)^5) -> 8.5749344e+08 | X18: =$B$16/(1+X17)^1+$C$16/(1+X17)^2+$D$16/(1+X17)^3+$E$16/(1+X17)^4+$F$16/(1+X17)^5+$F$16*(1+$I$14)/((X17-$I$14)*(1+X17)^5) -> 1.0107947e+09 | Y18: =$B$16/(1+Y17)^1+$C$16/(1+Y17)^2+$D$16/(1+Y17)^3+$E$16/(1+Y17)^4+$F$16/(1+Y17)^5+$F$16*(1+$I$14)/((Y17-$I$14)*(1+Y17)^5) -> 1.1096188e+09 | Z18: =$B$16/(1+Z17)^1+$C$16/(1+Z17)^2+$D$16/(1+Z17)^3+$E$16/(1+Z17)^4+$F$16/(1+Z17)^5+$F$16*(1+$I$14)/((Z17-$I$14)*(1+Z17)^5) -> 1.0579343e+09 | ... AM18: =$B$16/(1+AM17)^1+$C$16/(1+AM17)^2+$D$16/(1+AM17)^3+$E$16/(1+AM17)^4+$F$16/(1+AM17)^5+$F$16*(1+$I$14)/((AM17-$I$14)*(1+AM17)^5) -> 1.0481237e+09
A20: Base Case DCF | B20: Formula / Rationale | F20: Value | H20: Reverse DCF Summary | M20: Implied | N20: Base | O20: Diff. | P20: % | R20: Implied WACC | W20: =AM17 -> 0.049875913
A21: Terminal Value | B21: FCFfinal year * (1+g)/WACC-g | F21: =F16*(1+I14)/(I13-I14) -> 8.5543194e+08 | H21: Target EV | M21: =W3 -> 1048127860 | N21: =F23 -> 7.4071129e+08 | O21: =M21-N21 -> 3.0741657e+08 | P21: =(M21-N21)/N21 -> 0.41502887 | R21: Base WACC | W21: =I13 -> 0.06
A22: Present Value of Terminal Value | B22: Terminal Value / (1+WACC)n | F22: =F21/(1+I13)^5 -> 6.3922851e+08 | H22: Terminal Growth (g) Only | M22: =W9 -> 0.036109847 | N22: =I14 -> 0.025 | O22: =M22-N22 -> 0.011109847 | P22: =(M22-N22)/N22 -> 0.44439387 | R22: ΔWACC (Implied − Base) | W22: =W20-W21 -> -0.010124087 | X22: =(W20/(W21))-1 -> -0.16873479
A23: Enterprise Value (EV) | B23: PV of FCFs + PV of Terminal Value | F23: =SUM(B17:F17)+F22 -> 7.4071129e+08 | H23: WACC Only | M23: =W20 -> 0.049875913 | N23: =I13 -> 0.06 | O23: =M23-N23 -> -0.010124087 | P23: =(M23-N23)/N23 -> -0.16873479
A24: From Balance Sheet: Cash and Cash Equivalents | F24: ='Data Schema'!C21 -> 10727000 | H24: Revenue Growth Only | M24: =W36 -> 0.19823985 | N24: =W37 -> 0.1 | O24: =M24-N24 -> 0.098239851 | P24: =(M24-N24)/N24 -> 0.98239851 | R24: Scenario 3: Implied Revenue Growth — Shadow DCF + Binary Search
A25: From Balance Sheet: Total Debt | F25: ='Data Schema'!C31 -> 67095000 | H25: Blended Approach (1/3 weight from each) | M25: Implied | N25: Base | O25: Diff. | P25: %
A26: Equity Value | B26: EV - Total Debt + Cash and Cash Equipvalents | F26: =F23-F25+F24 -> 6.8434329e+08 | H26: g | M26: =W41 -> 0.028703282 | N26: =I14 -> 0.025 | O26: =M26-N26 -> 0.0037032823 | P26: =(M26-N26)/N26 -> 0.14813129 | R26: FCFF Margin Factor (m) | W26: =(1-I4-I5)*(1-I10)+I6-I11 -> 0.02725
A27: Shares Outstanding | F27: ='Data Schema'!B17 -> 8022000 | H27: WACC | M27: =W42 -> 0.056625304 | N27: =I13 -> 0.06 | O27: =M27-N27 -> -0.0033746958 | P27: =(M27-N27)/N27 -> -0.05624493 | R27: Base Revenue (R₀) | W27: =B3/(1+I2) -> 713163000
A28: Intrinsic Value per Share | B28: Equity Value / Shares Outstanding | F28: =F26/F27 -> 85.308313 | H28: Revenue Growth | M28: =W43 -> 0.13274662 | N28: =I2 -> 0.1 | O28: =M28-N28 -> 0.032746617 | P28: =(M28-N28)/N28 -> 0.32746617
A29: Current Stock Price | F29: =Calculations!B77 -> 123.63 | H29: Blended EV | M29: =W45 -> 1.0365644e+09 | N29: =F23 -> 7.4071129e+08 | O29: =M29-N29 -> 2.9585312e+08 | P29: =(M29-N29)/N29 -> 0.39941759 | R29: Iteration | S29: Start | T29: 1 | U29: 2 | V29: 3 | W29: 4 | X29: 5 | Y29: 6 | Z29: 7 | AA29: 8 | AB29: 9 | AC29: 10 | AD29: 11 | AE29: 12 | AF29: 13 | AG29: 14 | AH29: 15 | AI29: 16 | AJ29: 17 | AK29: 18 | AL29: 19 | AM29: 20
A30: Valuation Gap % | B30: (Intrinsic Value - Market Price) / Market Price | F30: =(F28-F29)/F29 -> -0.30997077 | H30: Blended Intrinsic Value | J30: VS Market Price: | L30: =W48 -> -0.01165953 | M30: =W47 -> 122.18853 | N30: =F28 -> 85.308313 | O30: =M30-N30 -> 36.880219 | P30: =(M30-N30)/N30 -> 0.43231682 | R30: Low | S30: 0 | T30: =IF(S34>$W$3,S30,S32) -> 0.15 | U30: =IF(T34>$W$3,T30,T32) -> 0.15 | V30: =IF(U34>$W$3,U30,U32) -> 0.1875 | W30: =IF(V34>$W$3,V30,V32) -> 0.1875 | X30: =IF(W34>$W$3,W30,W32) -> 0.196875 | Y30: =IF(X34>$W$3,X30,X32) -> 0.196875 | Z30: =IF(Y34>$W$3,Y30,Y32) -> 0.196875 | AA30: =IF(Z34>$W$3,Z30,Z32) -> 0.19804688 | ... AM30: =IF(AL34>$W$3,AL30,AL32) -> 0.19823971
A31: IRR (5-Year) | B31: (IV/Price)^(1/5) - 1 | F31: =IFERROR((F28/F29)^(1/5)-1,0) -> -0.071517981 | R31: High | S31: 0.3 | T31: =IF(S34>$W$3,S32,S31) -> 0.3 | U31: =IF(T34>$W$3,T32,T31) -> 0.225 | V31: =IF(U34>$W$3,U32,U31) -> 0.225 | W31: =IF(V34>$W$3,V32,V31) -> 0.20625 | X31: =IF(W34>$W$3,W32,W31) -> 0.20625 | Y31: =IF(X34>$W$3,X32,X31) -> 0.2015625 | Z31: =IF(Y34>$W$3,Y32,Y31) -> 0.19921875 | AA31: =IF(Z34>$W$3,Z32,Z31) -> 0.19921875 | ... AM31: =IF(AL34>$W$3,AL32,AL31) -> 0.19823999
A32: 5-Year Total Return % | B32: (IV/Price - 1) × 100% | F32: =F28/F29-1 -> -0.30997077 | R32: Mid (Trial Growth) | S32: =(S30+S31)/2 -> 0.15 | T32: =(T30+T31)/2 -> 0.225 | U32: =(U30+U31)/2 -> 0.1875 | V32: =(V30+V31)/2 -> 0.20625 | W32: =(W30+W31)/2 -> 0.196875 | X32: =(X30+X31)/2 -> 0.2015625 | Y32: =(Y30+Y31)/2 -> 0.19921875 | Z32: =(Z30+Z31)/2 -> 0.19804688 | ... AM32: =(AM30+AM31)/2 -> 0.19823985
R33: FCFF Factor (k) | S33: =(1+S32)*$W$26-S32*$I$12 -> 0.0283375 | T33: =(1+T32)*$W$26-T32*$I$12 -> 0.02888125 | U33: =(1+U32)*$W$26-U32*$I$12 -> 0.028609375 | V33: =(1+V32)*$W$26-V32*$I$12 -> 0.028745313 | W33: =(1+W32)*$W$26-W32*$I$12 -> 0.028677344 | X33: =(1+X32)*$W$26-X32*$I$12 -> 0.028711328 | Y33: =(1+Y32)*$W$26-Y32*$I$12 -> 0.028694336 | Z33: =(1+Z32)*$W$26-Z32*$I$12 -> 0.02868584 | ... AM33: =(1+AM32)*$W$26-AM32*$I$12 -> 0.028687239
A34: Bull Case DCF | H34: DCF Scenario Controller | R34: Shadow EV | S34: =$W$27*S33*(1/(1+$I$13)+(1+S32)/(1+$I$13)^2+(1+S32)^2/(1+$I$13)^3+(1+S32)^3/(1+$I$13)^4+(1+S32)^4/(1+$I$13)^5+(1+S32)^4*(1+$I$14)/(($I$13-$I$14)*(1+$I$13)^5)) -> 8.8646201e+08 | T34: =$W$27*T33*(1/(1+$I$13)+(1+T32)/(1+$I$13)^2+(1+T32)^2/(1+$I$13)^3+(1+T32)^3/(1+$I$13)^4+(1+T32)^4/(1+$I$13)^5+(1+T32)^4*(1+$I$14)/(($I$13-$I$14)*(1+$I$13)^5)) -> 1.147511e+09 | U34: =$W$27*U33*(1/(1+$I$13)+(1+U32)/(1+$I$13)^2+(1+U32)^2/(1+$I$13)^3+(1+U32)^3/(1+$I$13)^4+(1+U32)^4/(1+$I$13)^5+(1+U32)^4*(1+$I$14)/(($I$13-$I$14)*(1+$I$13)^5)) -> 1.0102379e+09 | V34: =$W$27*V33*(1/(1+$I$13)+(1+V32)/(1+$I$13)^2+(1+V32)^2/(1+$I$13)^3+(1+V32)^3/(1+$I$13)^4+(1+V32)^4/(1+$I$13)^5+(1+V32)^4*(1+$I$14)/(($I$13-$I$14)*(1+$I$13)^5)) -> 1.0771233e+09 | W34: =$W$27*W33*(1/(1+$I$13)+(1+W32)/(1+$I$13)^2+(1+W32)^2/(1+$I$13)^3+(1+W32)^3/(1+$I$13)^4+(1+W32)^4/(1+$I$13)^5+(1+W32)^4*(1+$I$14)/(($I$13-$I$14)*(1+$I$13)^5)) -> 1.0432509e+09 | X34: =$W$27*X33*(1/(1+$I$13)+(1+X32)/(1+$I$13)^2+(1+X32)^2/(1+$I$13)^3+(1+X32)^3/(1+$I$13)^4+(1+X32)^4/(1+$I$13)^5+(1+X32)^4*(1+$I$14)/(($I$13-$I$14)*(1+$I$13)^5)) -> 1.0600787e+09 | Y34: =$W$27*Y33*(1/(1+$I$13)+(1+Y32)/(1+$I$13)^2+(1+Y32)^2/(1+$I$13)^3+(1+Y32)^3/(1+$I$13)^4+(1+Y32)^4/(1+$I$13)^5+(1+Y32)^4*(1+$I$14)/(($I$13-$I$14)*(1+$I$13)^5)) -> 1.0516378e+09 | Z34: =$W$27*Z33*(1/(1+$I$13)+(1+Z32)/(1+$I$13)^2+(1+Z32)^2/(1+$I$13)^3+(1+Z32)^3/(1+$I$13)^4+(1+Z32)^4/(1+$I$13)^5+(1+Z32)^4*(1+$I$14)/(($I$13-$I$14)*(1+$I$13)^5)) -> 1.0474376e+09 | ... AM34: =$W$27*AM33*(1/(1+$I$13)+(1+AM32)/(1+$I$13)^2+(1+AM32)^2/(1+$I$13)^3+(1+AM32)^3/(1+$I$13)^4+(1+AM32)^4/(1+$I$13)^5+(1+AM32)^4*(1+$I$14)/(($I$13-$I$14)*(1+$I$13)^5)) -> 1.0481284e+09
A35: Bull Case Forecasted Data (in thousands) | B35: =B2+0 -> 2027 | C35: =B2+1 -> 2028 | D35: =B2+2 -> 2029 | E35: =B2+3 -> 2030 | F35: =B2+4 -> 2031 | H35: Parameter | I35: Bull Case Adj. | J35: Bear Case Adj. | K35: Description
A36: Total Revenue (Net Sales)* | B36: ='Data Schema'!C3*(1+$I$41) -> 8.0587419e+08 | C36: =B36*(1+$I$41) -> 9.1063783e+08 | D36: =C36*(1+$I$41) -> 1.0290208e+09 | E36: =D36*(1+$I$41) -> 1.1627935e+09 | F36: =E36*(1+$I$41) -> 1.3139566e+09 | H36: Revenue Growth % | I36: 0.3 | J36: -0.7 | K36: Multiplier on base growth | R36: Implied Rev Growth | W36: =AM32 -> 0.19823985
A37: less COGS/ Cost of Revenue | B37: =B36*$I$4 -> 6.0440564e+08 | C37: =C36*$I$4 -> 6.8297838e+08 | D37: =D36*$I$4 -> 7.7176556e+08 | E37: =E36*$I$4 -> 8.7209509e+08 | F37: =F36*$I$4 -> 9.8546745e+08 | H37: WACC % | I37: -0.15 | J37: 0.4 | K37: Multiplier on base WACC | R37: Base Rev Growth | W37: =I2 -> 0.1
A38: Gross Profit | B38: =B36-B37 -> 2.0146855e+08 | C38: =C36-C37 -> 2.2765946e+08 | D38: =D36-D37 -> 2.5725519e+08 | E38: =E36-E37 -> 2.9069836e+08 | F38: =F36-F37 -> 3.2848915e+08 | H38: Terminal Growth % | I38: 0.2 | J38: -0.4 | K38: Multiplier on base g | R38: ΔRev Growth (Implied − Base) | W38: =W36-W37 -> 0.098239851 | X38: =(W36/(W37))-1 -> 0.98239851
A39: less OpEx | B39: =B36*($I$5-$I$39) -> 1.5069847e+08 | C39: =C36*($I$5-$I$39) -> 1.7028928e+08 | D39: =D36*($I$5-$I$39) -> 1.9242688e+08 | E39: =E36*($I$5-$I$39) -> 2.1744238e+08 | F39: =F36*($I$5-$I$39) -> 2.4570988e+08 | H39: Op Margin % (abs) | I39: 0.02 | J39: -0.02 | K39: Absolute addition to margin
A40: Operating Income (EBIT) | B40: =B38-B39 -> 50770074 | C40: =C38-C39 -> 57370184 | D40: =D38-D39 -> 64828307 | E40: =E38-E39 -> 73255987 | F40: =F38-F39 -> 82779266 | H40: Adjusted Values | I40: Bull Case | J40: Bear Case | K40: Base Value | R40: Scenario 4: Blended Adjustment (1/3 Weight Each)
A41: less Interest Expense | B41: =$I$8*$I$9 -> 2400000 | C41: =$I$8*$I$9 -> 2400000 | D41: =$I$8*$I$9 -> 2400000 | E41: =$I$8*$I$9 -> 2400000 | F41: =$I$8*$I$9 -> 2400000 | H41: Revenue Growth | I41: =K41*(1+I36) -> 0.13 | J41: =K41*(1+J36) -> 0.03 | K41: =I2 -> 0.1 | R41: Blended g | W41: =I14+(W9-I14)/3 -> 0.028703282
...

Sheet Data Schema
A1: Historical Data from 10K all numbers in thousands | B1: TTM | C1: =D1+1 -> 2026 | D1: =E1+1 -> 2025 | E1: =F1+1 -> 2024 | F1: =YEAR('Raw Data Pasting'!A7) -> 2023 | G1: 0
A2: Income Statement Items (column A Data Tab) | G2: 0
A3: Total Revenue (Net Sales)* | B3: {=IFERROR(INDEX('Raw Data Pasting'!$A:$A, MATCH("Total Revenue", 'Raw Data Pasting'!$A:$A, 0) + MATCH(B$1, $B$1:$F$1, 0)),0)} -> 713163000 | C3: {=IFERROR(INDEX('Raw Data Pasting'!$A:$A, MATCH("Total Revenue", 'Raw Data Pasting'!$A:$A, 0) + MATCH(C$1, $B$1:$F$1, 0)),0)} -> 713163000 | D3: {=IFERROR(INDEX('Raw Data Pasting'!$A:$A, MATCH("Total Revenue", 'Raw Data Pasting'!$A:$A, 0) + MATCH(D$1, $B$1:$F$1, 0)),0)} -> 680985000 | E3: {=IFERROR(INDEX('Raw Data Pasting'!$A:$A, MATCH("Total Revenue", 'Raw Data Pasting'!$A:$A, 0) + MATCH(E$1, $B$1:$F$1, 0)),0)} -> 648125000 | F3: {=IFERROR(INDEX('Raw Data Pasting'!$A:$A, MATCH("Total Revenue", 'Raw Data Pasting'!$A:$A, 0) + MATCH(F$1, $B$1:$F$1, 0)),0)} -> 611289000 | G3: 0
A4: less COGS/ Cost of Revenue | B4: {=IFERROR(INDEX('Raw Data Pasting'!$A:$A, MATCH("Cost Of Revenue", 'Raw Data Pasting'!$A:$A, 0) + MATCH(B$1, $B$1:$F$1, 0)),0)} -> 535395000 | C4: {=IFERROR(INDEX('Raw Data Pasting'!$A:$A, MATCH("Cost Of Revenue", 'Raw Data Pasting'!$A:$A, 0) + MATCH(C$1, $B$1:$F$1, 0)),0)} -> 535395000 | D4: {=IFERROR(INDEX('Raw Data Pasting'!$A:$A, MATCH("Cost Of Revenue", 'Raw Data Pasting'!$A:$A, 0) + MATCH(D$1, $B$1:$F$1, 0)),0)} -> 511753000 | E4: {=IFERROR(INDEX('Raw Data Pasting'!$A:$A, MATCH("Cost Of Revenue", 'Raw Data Pasting'!$A:$A, 0) + MATCH(E$1, $B$1:$F$1, 0)),0)} -> 490142000 | F4: {=IFERROR(INDEX('Raw Data Pasting'!$A:$A, MATCH("Cost Of Revenue", 'Raw Data Pasting'!$A:$A, 0) + MATCH(F$1, $B$1:$F$1, 0)),0)} -> 463721000 | G4: 0
A5: Gross Profit | B5: {=IFERROR(INDEX('Raw Data Pasting'!$A:$A, MATCH("Gross Profit", 'Raw Data Pasting'!$A:$A, 0) + MATCH(B$1, $B$1:$F$1, 0)),0)} -> 177768000 | C5: {=IFERROR(INDEX('Raw Data Pasting'!$A:$A, MATCH("Gross Profit", 'Raw Data Pasting'!$A:$A, 0) + MATCH(C$1, $B$1:$F$1, 0)),0)} -> 177768000 | D5: {=IFERROR(INDEX('Raw Data Pasting'!$A:$A, MATCH("Gross Profit", 'Raw Data Pasting'!$A:$A, 0) + MATCH(D$1, $B$1:$F$1, 0)),0)} -> 169232000 | E5: {=IFERROR(INDEX('Raw Data Pasting'!$A:$A, MATCH("Gross Profit", 'Raw Data Pasting'!$A:$A, 0) + MATCH(E$1, $B$1:$F$1, 0)),0)} -> 157983000 | F5: {=IFERROR(INDEX('Raw Data Pasting'!$A:$A, MATCH("Gross Profit", 'Raw Data Pasting'!$A:$A, 0) + MATCH(F$1, $B$1:$F$1, 0)),0)} -> 147568000 | G5: 0
A6: less Op Ex / Non Interest Ex | B6: {=IFERROR( IF(INDEX('Raw Data Pasting'!$A:$A, MATCH("Operating Expense", 'Raw Data Pasting'!$A:$A, 0) + MATCH(B$1, $B$1:$F$1, 0))="--", 0, INDEX('Raw Data Pasting'!$A:$A, MATCH("Operating Expense", 'Raw Data Pasting'!$A:$A, 0) + MATCH(B$1, $B$1:$F$1, 0))), IFERROR( IF(INDEX('Raw Data Pasting'!$A:$A, MATCH("Non Interest Expense", 'Raw Data Pasting'!$A:$A, 0) + MATCH(B$1, $B$1:$F$1, 0))="--", 0, INDEX('Raw Data Pasting'!$A:$A, MATCH("Non Interest Expense", 'Raw Data Pasting'!$A:$A, 0) + MATCH(B$1, $B$1:$F$1, 0))), "N/A" ) )} -> 147943000 | C6: {=IFERROR( IF(INDEX('Raw Data Pasting'!$A:$A, MATCH("Operating Expense", 'Raw Data Pasting'!$A:$A, 0) + MATCH(C$1, $B$1:$F$1, 0))="--", 0, INDEX('Raw Data Pasting'!$A:$A, MATCH("Operating Expense", 'Raw Data Pasting'!$A:$A, 0) + MATCH(C$1, $B$1:$F$1, 0))), IFERROR( IF(INDEX('Raw Data Pasting'!$A:$A, MATCH("Non Interest Expense", 'Raw Data Pasting'!$A:$A, 0) + MATCH(C$1, $B$1:$F$1, 0))="--", 0, INDEX('Raw Data Pasting'!$A:$A, MATCH("Non Interest Expense", 'Raw Data Pasting'!$A:$A, 0) + MATCH(C$1, $B$1:$F$1, 0))), "N/A" ) )} -> 147943000 | D6: {=IFERROR( IF(INDEX('Raw Data Pasting'!$A:$A, MATCH("Operating Expense", 'Raw Data Pasting'!$A:$A, 0) + MATCH(D$1, $B$1:$F$1, 0))="--", 0, INDEX('Raw Data Pasting'!$A:$A, MATCH("Operating Expense", 'Raw Data Pasting'!$A:$A, 0) + MATCH(D$1, $B$1:$F$1, 0))), IFERROR( IF(INDEX('Raw Data Pasting'!$A:$A, MATCH("Non Interest Expense", 'Raw Data Pasting'!$A:$A, 0) + MATCH(D$1, $B$1:$F$1, 0))="--", 0, INDEX('Raw Data Pasting'!$A:$A, MATCH("Non Interest Expense", 'Raw Data Pasting'!$A:$A, 0) + MATCH(D$1, $B$1:$F$1, 0))), "N/A" ) )} -> 139884000 | E6: {=IFERROR( IF(INDEX('Raw Data Pasting'!$A:$A, MATCH("Operating Expense", 'Raw Data Pasting'!$A:$A, 0) + MATCH(E$1, $B$1:$F$1, 0))="--", 0, INDEX('Raw Data Pasting'!$A:$A, MATCH("Operating Expense", 'Raw Data Pasting'!$A:$A, 0) + MATCH(E$1, $B$1:$F$1, 0))), IFERROR( IF(INDEX('Raw Data Pasting'!$A:$A, MATCH("Non Interest Expense", 'Raw Data Pasting'!$A:$A, 0) + MATCH(E$1, $B$1:$F$1, 0))="--", 0, INDEX('Raw Data Pasting'!$A:$A, MATCH("Non Interest Expense", 'Raw Data Pasting'!$A:$A, 0) + MATCH(E$1, $B$1:$F$1, 0))), "N/A" ) )} -> 130971000 | F6: {=IFERROR( IF(INDEX('Raw Data Pasting'!$A:$A, MATCH("Operating Expense", 'Raw Data Pasting'!$A:$A, 0) + MATCH(F$1, $B$1:$F$1, 0))="--", 0, INDEX('Raw Data Pasting'!$A:$A, MATCH("Operating Expense", 'Raw Data Pasting'!$A:$A, 0) + MATCH(F$1, $B$1:$F$1, 0))), IFERROR( IF(INDEX('Raw Data Pasting'!$A:$A, MATCH("Non Interest Expense", 'Raw Data Pasting'!$A:$A, 0) + MATCH(F$1, $B$1:$F$1, 0))="--", 0, INDEX('Raw Data Pasting'!$A:$A, MATCH("Non Interest Expense", 'Raw Data Pasting'!$A:$A, 0) + MATCH(F$1, $B$1:$F$1, 0))), "N/A" ) )} -> 127140000 | G6: 0
A7: Operating Income (EBIT) | B7: {=IFERROR(INDEX('Raw Data Pasting'!$A:$A, MATCH("Operating Income", 'Raw Data Pasting'!$A:$A, 0) + MATCH(B$1, $B$1:$F$1, 0)),0)} -> 29825000 | C7: {=IFERROR(INDEX('Raw Data Pasting'!$A:$A, MATCH("Operating Income", 'Raw Data Pasting'!$A:$A, 0) + MATCH(C$1, $B$1:$F$1, 0)),0)} -> 29825000 | D7: {=IFERROR(INDEX('Raw Data Pasting'!$A:$A, MATCH("Operating Income", 'Raw Data Pasting'!$A:$A, 0) + MATCH(D$1, $B$1:$F$1, 0)),0)} -> 29348000 | E7: {=IFERROR(INDEX('Raw Data Pasting'!$A:$A, MATCH("Operating Income", 'Raw Data Pasting'!$A:$A, 0) + MATCH(E$1, $B$1:$F$1, 0)),0)} -> 27012000 | F7: {=IFERROR(INDEX('Raw Data Pasting'!$A:$A, MATCH("Operating Income", 'Raw Data Pasting'!$A:$A, 0) + MATCH(F$1, $B$1:$F$1, 0)),0)} -> 20428000 | G7: 0
A8: add Interest Income (Non Op) | B8: {=IFERROR(INDEX('Raw Data Pasting'!$A:$A, MATCH("Interest Income", 'Raw Data Pasting'!$A:$A, 0) + MATCH(B$1, $B$1:$F$1, 0)),0)} -> 368000 | C8: {=IFERROR(INDEX('Raw Data Pasting'!$A:$A, MATCH("Interest Income", 'Raw Data Pasting'!$A:$A, 0) + MATCH(C$1, $B$1:$F$1, 0)),0)} -> 368000 | D8: {=IFERROR(INDEX('Raw Data Pasting'!$A:$A, MATCH("Interest Income", 'Raw Data Pasting'!$A:$A, 0) + MATCH(D$1, $B$1:$F$1, 0)),0)} -> 483000 | E8: {=IFERROR(INDEX('Raw Data Pasting'!$A:$A, MATCH("Interest Income", 'Raw Data Pasting'!$A:$A, 0) + MATCH(E$1, $B$1:$F$1, 0)),0)} -> 546000 | F8: {=IFERROR(INDEX('Raw Data Pasting'!$A:$A, MATCH("Interest Income", 'Raw Data Pasting'!$A:$A, 0) + MATCH(F$1, $B$1:$F$1, 0)),0)} -> 254000 | G8: 0
A9: less Interest Expense (Non Op) | B9: {=IFERROR(INDEX('Raw Data Pasting'!$A:$A, MATCH("Interest Expense", 'Raw Data Pasting'!$A:$A, 0) + MATCH(B$1, $B$1:$F$1, 0)),0)} -> 2799000 | C9: {=IFERROR(INDEX('Raw Data Pasting'!$A:$A, MATCH("Interest Expense", 'Raw Data Pasting'!$A:$A, 0) + MATCH(C$1, $B$1:$F$1, 0)),0)} -> 2799000 | D9: {=IFERROR(INDEX('Raw Data Pasting'!$A:$A, MATCH("Interest Expense", 'Raw Data Pasting'!$A:$A, 0) + MATCH(D$1, $B$1:$F$1, 0)),0)} -> 2728000 | E9: {=IFERROR(INDEX('Raw Data Pasting'!$A:$A, MATCH("Interest Expense", 'Raw Data Pasting'!$A:$A, 0) + MATCH(E$1, $B$1:$F$1, 0)),0)} -> 2683000 | F9: {=IFERROR(INDEX('Raw Data Pasting'!$A:$A, MATCH("Interest Expense", 'Raw Data Pasting'!$A:$A, 0) + MATCH(F$1, $B$1:$F$1, 0)),0)} -> 2128000 | G9: 0
A10: add Other Special Income | B10: {=IFERROR(IF(INDEX('Raw Data Pasting'!$A:$A,MATCH("Other Income Expense",'Raw Data Pasting'!$A:$A,0)+MATCH(B$1,$B$1:$F$1,0))="--",0,(INDEX('Raw Data Pasting'!$A:$A,MATCH("Other Income Expense",'Raw Data Pasting'!$A:$A,0)+MATCH(B$1,$B$1:$F$1,0)))), "N/A")} -> 2075000 | C10: {=IFERROR(IF(INDEX('Raw Data Pasting'!$A:$A,MATCH("Other Income Expense",'Raw Data Pasting'!$A:$A,0)+MATCH(C$1,$B$1:$F$1,0))="--",0,(INDEX('Raw Data Pasting'!$A:$A,MATCH("Other Income Expense",'Raw Data Pasting'!$A:$A,0)+MATCH(C$1,$B$1:$F$1,0)))), "N/A")} -> 2075000 | D10: {=IFERROR(IF(INDEX('Raw Data Pasting'!$A:$A,MATCH("Other Income Expense",'Raw Data Pasting'!$A:$A,0)+MATCH(D$1,$B$1:$F$1,0))="--",0,(INDEX('Raw Data Pasting'!$A:$A,MATCH("Other Income Expense",'Raw Data Pasting'!$A:$A,0)+MATCH(D$1,$B$1:$F$1,0)))), "N/A")} -> -794000 | E10: {=IFERROR(IF(INDEX('Raw Data Pasting'!$A:$A,MATCH("Other Income Expense",'Raw Data Pasting'!$A:$A,0)+MATCH(E$1,$B$1:$F$1,0))="--",0,(INDEX('Raw Data Pasting'!$A:$A,MATCH("Other Income Expense",'Raw Data Pasting'!$A:$A,0)+MATCH(E$1,$B$1:$F$1,0)))), "N/A")} -> -3027000 | F10: {=IFERROR(IF(INDEX('Raw Data Pasting'!$A:$A,MATCH("Other Income Expense",'Raw Data Pasting'!$A:$A,0)+MATCH(F$1,$B$1:$F$1,0))="--",0,(INDEX('Raw Data Pasting'!$A:$A,MATCH("Other Income Expense",'Raw Data Pasting'!$A:$A,0)+MATCH(F$1,$B$1:$F$1,0)))), "N/A")} -> -1538000 | G10: 0
A11: Earnings Before Tax (Pretax Income) | B11: {=IFERROR(INDEX('Raw Data Pasting'!$A:$A, MATCH("Pretax Income", 'Raw Data Pasting'!$A:$A, 0) + MATCH(B$1, $B$1:$F$1, 0)),0)} -> 29469000 | C11: {=IFERROR(INDEX('Raw Data Pasting'!$A:$A, MATCH("Pretax Income", 'Raw Data Pasting'!$A:$A, 0) + MATCH(C$1, $B$1:$F$1, 0)),0)} -> 29469000 | D11: {=IFERROR(INDEX('Raw Data Pasting'!$A:$A, MATCH("Pretax Income", 'Raw Data Pasting'!$A:$A, 0) + MATCH(D$1, $B$1:$F$1, 0)),0)} -> 26309000 | E11: {=IFERROR(INDEX('Raw Data Pasting'!$A:$A, MATCH("Pretax Income", 'Raw Data Pasting'!$A:$A, 0) + MATCH(E$1, $B$1:$F$1, 0)),0)} -> 21848000 | F11: {=IFERROR(INDEX('Raw Data Pasting'!$A:$A, MATCH("Pretax Income", 'Raw Data Pasting'!$A:$A, 0) + MATCH(F$1, $B$1:$F$1, 0)),0)} -> 17016000 | G11: 0
A12: less Income Tax Expense/Tax Provision | B12: {=IFERROR(INDEX('Raw Data Pasting'!$A:$A, MATCH("Tax Provision", 'Raw Data Pasting'!$A:$A, 0) + MATCH(B$1, $B$1:$F$1, 0)),0)} -> 7199000 | C12: {=IFERROR(INDEX('Raw Data Pasting'!$A:$A, MATCH("Tax Provision", 'Raw Data Pasting'!$A:$A, 0) + MATCH(C$1, $B$1:$F$1, 0)),0)} -> 7199000 | D12: {=IFERROR(INDEX('Raw Data Pasting'!$A:$A, MATCH("Tax Provision", 'Raw Data Pasting'!$A:$A, 0) + MATCH(D$1, $B$1:$F$1, 0)),0)} -> 6152000 | E12: {=IFERROR(INDEX('Raw Data Pasting'!$A:$A, MATCH("Tax Provision", 'Raw Data Pasting'!$A:$A, 0) + MATCH(E$1, $B$1:$F$1, 0)),0)} -> 5578000 | F12: {=IFERROR(INDEX('Raw Data Pasting'!$A:$A, MATCH("Tax Provision", 'Raw Data Pasting'!$A:$A, 0) + MATCH(F$1, $B$1:$F$1, 0)),0)} -> 5724000 | G12: 0
A13: Net Income (Common Stockholders) | B13: {=IFERROR(INDEX('Raw Data Pasting'!$A:$A, MATCH("Net Income Common Stockholders", 'Raw Data Pasting'!$A:$A, 0) + MATCH(B$1, $B$1:$F$1, 0)),0)} -> 21893000 | C13: {=IFERROR(INDEX('Raw Data Pasting'!$A:$A, MATCH("Net Income Common Stockholders", 'Raw Data Pasting'!$A:$A, 0) + MATCH(C$1, $B$1:$F$1, 0)),0)} -> 21893000 | D13: {=IFERROR(INDEX('Raw Data Pasting'!$A:$A, MATCH("Net Income Common Stockholders", 'Raw Data Pasting'!$A:$A, 0) + MATCH(D$1, $B$1:$F$1, 0)),0)} -> 19436000 | E13: {=IFERROR(INDEX('Raw Data Pasting'!$A:$A, MATCH("Net Income Common Stockholders", 'Raw Data Pasting'!$A:$A, 0) + MATCH(E$1, $B$1:$F$1, 0)),0)} -> 15511000 | F13: {=IFERROR(INDEX('Raw Data Pasting'!$A:$A, MATCH("Net Income Common Stockholders", 'Raw Data Pasting'!$A:$A, 0) + MATCH(F$1, $B$1:$F$1, 0)),0)} -> 11680000 | G13: 0
A14: EBIT (Adjusted) | B14: {=IFERROR(INDEX('Raw Data Pasting'!$A:$A, MATCH("EBIT", 'Raw Data Pasting'!$A:$A, 0) + MATCH(B$1, $B$1:$F$1, 0)),0)} -> 32268000 | C14: {=IFERROR(INDEX('Raw Data Pasting'!$A:$A, MATCH("EBIT", 'Raw Data Pasting'!$A:$A, 0) + MATCH(C$1, $B$1:$F$1, 0)),0)} -> 32268000 | D14: {=IFERROR(INDEX('Raw Data Pasting'!$A:$A, MATCH("EBIT", 'Raw Data Pasting'!$A:$A, 0) + MATCH(D$1, $B$1:$F$1, 0)),0)} -> 29037000 | E14: {=IFERROR(INDEX('Raw Data Pasting'!$A:$A, MATCH("EBIT", 'Raw Data Pasting'!$A:$A, 0) + MATCH(E$1, $B$1:$F$1, 0)),0)} -> 24531000 | F14: {=IFERROR(INDEX('Raw Data Pasting'!$A:$A, MATCH("EBIT", 'Raw Data Pasting'!$A:$A, 0) + MATCH(F$1, $B$1:$F$1, 0)),0)} -> 19144000 | G14: 0
A15: EBITDA (Normalized) | B15: {=IFERROR(INDEX('Raw Data Pasting'!$A:$A, MATCH("Normalized EBITDA", 'Raw Data Pasting'!$A:$A, 0) + MATCH(B$1, $B$1:$F$1, 0)),0)} -> 46471000 | C15: {=IFERROR(INDEX('Raw Data Pasting'!$A:$A, MATCH("Normalized EBITDA", 'Raw Data Pasting'!$A:$A, 0) + MATCH(C$1, $B$1:$F$1, 0)),0)} -> 46471000 | D15: {=IFERROR(INDEX('Raw Data Pasting'!$A:$A, MATCH("Normalized EBITDA", 'Raw Data Pasting'!$A:$A, 0) + MATCH(D$1, $B$1:$F$1, 0)),0)} -> 42010000 | E15: {=IFERROR(INDEX('Raw Data Pasting'!$A:$A, MATCH("Normalized EBITDA", 'Raw Data Pasting'!$A:$A, 0) + MATCH(E$1, $B$1:$F$1, 0)),0)} -> 36384000 | F15: {=IFERROR(INDEX('Raw Data Pasting'!$A:$A, MATCH("Normalized EBITDA", 'Raw Data Pasting'!$A:$A, 0) + MATCH(F$1, $B$1:$F$1, 0)),0)} -> 30089000 | G15: 0
A16: EPS (Diluted) | B16: {=IFERROR(INDEX('Raw Data Pasting'!$A:$A, MATCH("Diluted EPS", 'Raw Data Pasting'!$A:$A, 0) + MATCH(B$1, $B$1:$F$1, 0)),0)} -> 2.73 | C16: {=IFERROR(INDEX('Raw Data Pasting'!$A:$A, MATCH("Diluted EPS", 'Raw Data Pasting'!$A:$A, 0) + MATCH(C$1, $B$1:$F$1, 0)),0)} -> 2.73 | D16: {=IFERROR(INDEX('Raw Data Pasting'!$A:$A, MATCH("Diluted EPS", 'Raw Data Pasting'!$A:$A, 0) + MATCH(D$1, $B$1:$F$1, 0)),0)} -> 2.41 | E16: {=IFERROR(INDEX('Raw Data Pasting'!$A:$A, MATCH("Diluted EPS", 'Raw Data Pasting'!$A:$A, 0) + MATCH(E$1, $B$1:$F$1, 0)),0)} -> 1.91 | F16: {=IFERROR(INDEX('Raw Data Pasting'!$A:$A, MATCH("Diluted EPS", 'Raw Data Pasting'!$A:$A, 0) + MATCH(F$1, $B$1:$F$1, 0)),0)} -> 1.42 | G16: 0
A17: Shares Outstanding (Diluted Average) | B17: {=IFERROR(INDEX('Raw Data Pasting'!$A:$A, MATCH("Diluted Average Shares", 'Raw Data Pasting'!$A:$A, 0) + MATCH(B$1, $B$1:$F$1, 0)),0)} -> 8022000 | C17: {=IFERROR(INDEX('Raw Data Pasting'!$A:$A, MATCH("Diluted Average Shares", 'Raw Data Pasting'!$A:$A, 0) + MATCH(C$1, $B$1:$F$1, 0)),0)} -> 8022000 | D17: {=IFERROR(INDEX('Raw Data Pasting'!$A:$A, MATCH("Diluted Average Shares", 'Raw Data Pasting'!$A:$A, 0) + MATCH(D$1, $B$1:$F$1, 0)),0)} -> 8081000 | E17: {=IFERROR(INDEX('Raw Data Pasting'!$A:$A, MATCH("Diluted Average Shares", 'Raw Data Pasting'!$A:$A, 0) + MATCH(E$1, $B$1:$F$1, 0)),0)} -> 8108000 | F17: {=IFERROR(INDEX('Raw Data Pasting'!$A:$A, MATCH("Diluted Average Shares", 'Raw Data Pasting'!$A:$A, 0) + MATCH(F$1, $B$1:$F$1, 0)),0)} -> 8202000 | G17: 0
A18: Balance Sheet Items (Column B)
A19: Total Assets | B19: {=IFERROR(INDEX('Raw Data Pasting'!$B:$B, MATCH("Total Assets", 'Raw Data Pasting'!$B:$B, 0) + MATCH(B$1, $C$1:$F$1, 0)),"N/A")} -> N/A | C19: {=IFERROR(INDEX('Raw Data Pasting'!$B:$B, MATCH("Total Assets", 'Raw Data Pasting'!$B:$B, 0) + MATCH(C$1, $C$1:$F$1, 0)),"N/A")} -> 284668000 | D19: {=IFERROR(INDEX('Raw Data Pasting'!$B:$B, MATCH("Total Assets", 'Raw Data Pasting'!$B:$B, 0) + MATCH(D$1, $C$1:$F$1, 0)),"N/A")} -> 260823000 | E19: {=IFERROR(INDEX('Raw Data Pasting'!$B:$B, MATCH("Total Assets", 'Raw Data Pasting'!$B:$B, 0) + MATCH(E$1, $C$1:$F$1, 0)),"N/A")} -> 252399000 | F19: {=IFERROR(INDEX('Raw Data Pasting'!$B:$B, MATCH("Total Assets", 'Raw Data Pasting'!$B:$B, 0) + MATCH(F$1, $C$1:$F$1, 0)),"N/A")} -> 243197000 | G19: 0
A20: Current Assets | B20: {=IFERROR(INDEX('Raw Data Pasting'!$B:$B, MATCH("Current Assets", 'Raw Data Pasting'!$B:$B, 0) + MATCH(B$1, $C$1:$F$1, 0)),"N/A")} -> N/A | C20: {=IFERROR(INDEX('Raw Data Pasting'!$B:$B, MATCH("Current Assets", 'Raw Data Pasting'!$B:$B, 0) + MATCH(C$1, $C$1:$F$1, 0)),"N/A")} -> 84874000 | D20: {=IFERROR(INDEX('Raw Data Pasting'!$B:$B, MATCH("Current Assets", 'Raw Data Pasting'!$B:$B, 0) + MATCH(D$1, $C$1:$F$1, 0)),"N/A")} -> 79458000 | E20: {=IFERROR(INDEX('Raw Data Pasting'!$B:$B, MATCH("Current Assets", 'Raw Data Pasting'!$B:$B, 0) + MATCH(E$1, $C$1:$F$1, 0)),"N/A")} -> 76877000 | F20: {=IFERROR(INDEX('Raw Data Pasting'!$B:$B, MATCH("Current Assets", 'Raw Data Pasting'!$B:$B, 0) + MATCH(F$1, $C$1:$F$1, 0)),"N/A")} -> 75655000 | G20: 0
A21: Cash, Cash Equivalents & Short Term Investments | B21: {=IFERROR(INDEX('Raw Data Pasting'!$B:$B, MATCH("Cash, Cash Equivalents & Short Term Investments", 'Raw Data Pasting'!$B:$B, 0) + MATCH(B$1, $C$1:$F$1, 0)),"N/A")} -> N/A | C21: {=IFERROR(INDEX('Raw Data Pasting'!$B:$B, MATCH("Cash, Cash Equivalents & Short Term Investments", 'Raw Data Pasting'!$B:$B, 0) + MATCH(C$1, $C$1:$F$1, 0)),"N/A")} -> 10727000 | D21: {=IFERROR(INDEX('Raw Data Pasting'!$B:$B, MATCH("Cash, Cash Equivalents & Short Term Investments", 'Raw Data Pasting'!$B:$B, 0) + MATCH(D$1, $C$1:$F$1, 0)),"N/A")} -> 9037000 | E21: {=IFERROR(INDEX('Raw Data Pasting'!$B:$B, MATCH("Cash, Cash Equivalents & Short Term Investments", 'Raw Data Pasting'!$B:$B, 0) + MATCH(E$1, $C$1:$F$1, 0)),"N/A")} -> 9867000 | F21: {=IFERROR(INDEX('Raw Data Pasting'!$B:$B, MATCH("Cash, Cash Equivalents & Short Term Investments", 'Raw Data Pasting'!$B:$B, 0) + MATCH(F$1, $C$1:$F$1, 0)),"N/A")} -> 8625000
A22: Cash Only (or Cash + Equivs only) | B22: {=IFERROR( IF(INDEX('Raw Data Pasting'!$B:$B,MATCH("Cash",'Raw Data Pasting'!$B:$B,0)+MATCH(B$1,$C$1:$F$1,0))="--",0,INDEX('Raw Data Pasting'!$B:$B,MATCH("Cash",'Raw Data Pasting'!$B:$B,0)+MATCH(B$1,$C$1:$F$1,0))), IFERROR( IF(INDEX('Raw Data Pasting'!$B:$B,MATCH("Cash And Cash Equivalents",'Raw Data Pasting'!$B:$B,0)+MATCH(B$1,$C$1:$F$1,0))="--",0,INDEX('Raw Data Pasting'!$B:$B,MATCH("Cash And Cash Equivalents",'Raw Data Pasting'!$B:$B,0)+MATCH(B$1,$C$1:$F$1,0))), "N/A" ))} -> N/A | C22: {=IFERROR( IF(INDEX('Raw Data Pasting'!$B:$B,MATCH("Cash",'Raw Data Pasting'!$B:$B,0)+MATCH(C$1,$C$1:$F$1,0))="--",0,INDEX('Raw Data Pasting'!$B:$B,MATCH("Cash",'Raw Data Pasting'!$B:$B,0)+MATCH(C$1,$C$1:$F$1,0))), IFERROR( IF(INDEX('Raw Data Pasting'!$B:$B,MATCH("Cash And Cash Equivalents",'Raw Data Pasting'!$B:$B,0)+MATCH(C$1,$C$1:$F$1,0))="--",0,INDEX('Raw Data Pasting'!$B:$B,MATCH("Cash And Cash Equivalents",'Raw Data Pasting'!$B:$B,0)+MATCH(C$1,$C$1:$F$1,0))), "N/A" ))} -> 10727000 | D22: {=IFERROR( IF(INDEX('Raw Data Pasting'!$B:$B,MATCH("Cash",'Raw Data Pasting'!$B:$B,0)+MATCH(D$1,$C$1:$F$1,0))="--",0,INDEX('Raw Data Pasting'!$B:$B,MATCH("Cash",'Raw Data Pasting'!$B:$B,0)+MATCH(D$1,$C$1:$F$1,0))), IFERROR( IF(INDEX('Raw Data Pasting'!$B:$B,MATCH("Cash And Cash Equivalents",'Raw Data Pasting'!$B:$B,0)+MATCH(D$1,$C$1:$F$1,0))="--",0,INDEX('Raw Data Pasting'!$B:$B,MATCH("Cash And Cash Equivalents",'Raw Data Pasting'!$B:$B,0)+MATCH(D$1,$C$1:$F$1,0))), "N/A" ))} -> 9037000 | E22: {=IFERROR( IF(INDEX('Raw Data Pasting'!$B:$B,MATCH("Cash",'Raw Data Pasting'!$B:$B,0)+MATCH(E$1,$C$1:$F$1,0))="--",0,INDEX('Raw Data Pasting'!$B:$B,MATCH("Cash",'Raw Data Pasting'!$B:$B,0)+MATCH(E$1,$C$1:$F$1,0))), IFERROR( IF(INDEX('Raw Data Pasting'!$B:$B,MATCH("Cash And Cash Equivalents",'Raw Data Pasting'!$B:$B,0)+MATCH(E$1,$C$1:$F$1,0))="--",0,INDEX('Raw Data Pasting'!$B:$B,MATCH("Cash And Cash Equivalents",'Raw Data Pasting'!$B:$B,0)+MATCH(E$1,$C$1:$F$1,0))), "N/A" ))} -> 9867000 | F22: {=IFERROR( IF(INDEX('Raw Data Pasting'!$B:$B,MATCH("Cash",'Raw Data Pasting'!$B:$B,0)+MATCH(F$1,$C$1:$F$1,0))="--",0,INDEX('Raw Data Pasting'!$B:$B,MATCH("Cash",'Raw Data Pasting'!$B:$B,0)+MATCH(F$1,$C$1:$F$1,0))), IFERROR( IF(INDEX('Raw Data Pasting'!$B:$B,MATCH("Cash And Cash Equivalents",'Raw Data Pasting'!$B:$B,0)+MATCH(F$1,$C$1:$F$1,0))="--",0,INDEX('Raw Data Pasting'!$B:$B,MATCH("Cash And Cash Equivalents",'Raw Data Pasting'!$B:$B,0)+MATCH(F$1,$C$1:$F$1,0))), "N/A" ))} -> 8625000 | G22: 0
A23: Accounts receivable | B23: {=IFERROR(INDEX('Raw Data Pasting'!$B:$B, MATCH("Accounts receivable", 'Raw Data Pasting'!$B:$B, 0) + MATCH(B$1, $C$1:$F$1, 0)),"N/A")} -> N/A | C23: {=IFERROR(INDEX('Raw Data Pasting'!$B:$B, MATCH("Accounts receivable", 'Raw Data Pasting'!$B:$B, 0) + MATCH(C$1, $C$1:$F$1, 0)),"N/A")} -> 11172000 | D23: {=IFERROR(INDEX('Raw Data Pasting'!$B:$B, MATCH("Accounts receivable", 'Raw Data Pasting'!$B:$B, 0) + MATCH(D$1, $C$1:$F$1, 0)),"N/A")} -> 9975000 | E23: {=IFERROR(INDEX('Raw Data Pasting'!$B:$B, MATCH("Accounts receivable", 'Raw Data Pasting'!$B:$B, 0) + MATCH(E$1, $C$1:$F$1, 0)),"N/A")} -> 8796000 | F23: {=IFERROR(INDEX('Raw Data Pasting'!$B:$B, MATCH("Accounts receivable", 'Raw Data Pasting'!$B:$B, 0) + MATCH(F$1, $C$1:$F$1, 0)),"N/A")} -> 7933000 | G23: 0
A24: Other Short Term Investments | B24: {=IFERROR(IF(INDEX('Raw Data Pasting'!$B:$B,MATCH("Other Short Term Investments",'Raw Data Pasting'!$B:$B,0)+MATCH(B$1,$C$1:$F$1,0))="--",0,(INDEX('Raw Data Pasting'!$B:$B,MATCH("Other Short Term Investments",'Raw Data Pasting'!$B:$B,0)+MATCH(B$1,$C$1:$F$1,0)))), 0)} -> 0 | C24: {=IFERROR(IF(INDEX('Raw Data Pasting'!$B:$B,MATCH("Other Short Term Investments",'Raw Data Pasting'!$B:$B,0)+MATCH(C$1,$C$1:$F$1,0))="--",0,(INDEX('Raw Data Pasting'!$B:$B,MATCH("Other Short Term Investments",'Raw Data Pasting'!$B:$B,0)+MATCH(C$1,$C$1:$F$1,0)))), 0)} -> 0 | D24: {=IFERROR(IF(INDEX('Raw Data Pasting'!$B:$B,MATCH("Other Short Term Investments",'Raw Data Pasting'!$B:$B,0)+MATCH(D$1,$C$1:$F$1,0))="--",0,(INDEX('Raw Data Pasting'!$B:$B,MATCH("Other Short Term Investments",'Raw Data Pasting'!$B:$B,0)+MATCH(D$1,$C$1:$F$1,0)))), 0)} -> 0 | E24: {=IFERROR(IF(INDEX('Raw Data Pasting'!$B:$B,MATCH("Other Short Term Investments",'Raw Data Pasting'!$B:$B,0)+MATCH(E$1,$C$1:$F$1,0))="--",0,(INDEX('Raw Data Pasting'!$B:$B,MATCH("Other Short Term Investments",'Raw Data Pasting'!$B:$B,0)+MATCH(E$1,$C$1:$F$1,0)))), 0)} -> 0 | F24: {=IFERROR(IF(INDEX('Raw Data Pasting'!$B:$B,MATCH("Other Short Term Investments",'Raw Data Pasting'!$B:$B,0)+MATCH(F$1,$C$1:$F$1,0))="--",0,(INDEX('Raw Data Pasting'!$B:$B,MATCH("Other Short Term Investments",'Raw Data Pasting'!$B:$B,0)+MATCH(F$1,$C$1:$F$1,0)))), 0)} -> 0 | G24: 0
A25: Inventory | B25: {=IFERROR(INDEX('Raw Data Pasting'!$B:$B, MATCH("Inventory", 'Raw Data Pasting'!$B:$B, 0) + MATCH(B$1, $C$1:$F$1, 0)),"N/A")} -> N/A | C25: {=IFERROR(INDEX('Raw Data Pasting'!$B:$B, MATCH("Inventory", 'Raw Data Pasting'!$B:$B, 0) + MATCH(C$1, $C$1:$F$1, 0)),"N/A")} -> 58851000 | D25: {=IFERROR(INDEX('Raw Data Pasting'!$B:$B, MATCH("Inventory", 'Raw Data Pasting'!$B:$B, 0) + MATCH(D$1, $C$1:$F$1, 0)),"N/A")} -> 56435000 | E25: {=IFERROR(INDEX('Raw Data Pasting'!$B:$B, MATCH("Inventory", 'Raw Data Pasting'!$B:$B, 0) + MATCH(E$1, $C$1:$F$1, 0)),"N/A")} -> 54892000 | F25: {=IFERROR(INDEX('Raw Data Pasting'!$B:$B, MATCH("Inventory", 'Raw Data Pasting'!$B:$B, 0) + MATCH(F$1, $C$1:$F$1, 0)),"N/A")} -> 56576000 | G25: 0
